{
 "cells": [
  {
   "cell_type": "code",
   "execution_count": 1,
   "metadata": {},
   "outputs": [],
   "source": [
    "import pandas as pd\n",
    "import numpy as np\n",
    "import matplotlib.pyplot as plt\n",
    "from os.path import join\n",
    "import cv2\n",
    "import tensorflow as tf\n",
    "from PIL import Image\n",
    "from tensorflow.keras.models import Sequential\n",
    "from tensorflow.keras.layers import Dense\n",
    "from tensorflow.keras import layers\n",
    "from tensorflow.keras import callbacks\n",
    "from tensorflow.keras.optimizers.legacy import Adam\n",
    "from tensorflow.keras import callbacks"
   ]
  },
  {
   "cell_type": "code",
   "execution_count": 2,
   "metadata": {},
   "outputs": [],
   "source": [
    "checkpoint_path = \"training_1/cp.ckpt\""
   ]
  },
  {
   "cell_type": "code",
   "execution_count": 3,
   "metadata": {},
   "outputs": [],
   "source": [
    "model = Sequential(\n",
    "    [\n",
    "        layers.Dropout(0.3),\n",
    "        Dense(100, activation='relu', input_shape=[784]),\n",
    "        layers.Dropout(0.3),\n",
    "        Dense(75, activation='relu'),\n",
    "        layers.Dropout(0.3),\n",
    "        Dense(50, activation='relu'),\n",
    "        Dense(10, activation='linear')\n",
    "    ]\n",
    ")"
   ]
  },
  {
   "cell_type": "code",
   "execution_count": 4,
   "metadata": {},
   "outputs": [],
   "source": [
    "# model.compile(\n",
    "#     loss = tf.keras.losses.SparseCategoricalCrossentropy(from_logits=True),\n",
    "#     optimizer = tf.keras.optimizers.legacy.Adam(0.0005),\n",
    "# )"
   ]
  },
  {
   "cell_type": "code",
   "execution_count": 5,
   "metadata": {},
   "outputs": [
    {
     "data": {
      "text/plain": [
       "<tensorflow.python.checkpoint.checkpoint.CheckpointLoadStatus at 0x17d0e5210>"
      ]
     },
     "execution_count": 5,
     "metadata": {},
     "output_type": "execute_result"
    }
   ],
   "source": [
    "model.load_weights(checkpoint_path)"
   ]
  },
  {
   "cell_type": "code",
   "execution_count": 6,
   "metadata": {},
   "outputs": [
    {
     "ename": "InvalidArgumentError",
     "evalue": "Graph execution error:\n\nDetected at node 'sequential/dense/Relu' defined at (most recent call last):\n    File \"<frozen runpy>\", line 198, in _run_module_as_main\n    File \"<frozen runpy>\", line 88, in _run_code\n    File \"/Users/utkarsh/miniconda3/lib/python3.11/site-packages/ipykernel_launcher.py\", line 17, in <module>\n      app.launch_new_instance()\n    File \"/Users/utkarsh/miniconda3/lib/python3.11/site-packages/traitlets/config/application.py\", line 1043, in launch_instance\n      app.start()\n    File \"/Users/utkarsh/miniconda3/lib/python3.11/site-packages/ipykernel/kernelapp.py\", line 736, in start\n      self.io_loop.start()\n    File \"/Users/utkarsh/miniconda3/lib/python3.11/site-packages/tornado/platform/asyncio.py\", line 195, in start\n      self.asyncio_loop.run_forever()\n    File \"/Users/utkarsh/miniconda3/lib/python3.11/asyncio/base_events.py\", line 607, in run_forever\n      self._run_once()\n    File \"/Users/utkarsh/miniconda3/lib/python3.11/asyncio/base_events.py\", line 1922, in _run_once\n      handle._run()\n    File \"/Users/utkarsh/miniconda3/lib/python3.11/asyncio/events.py\", line 80, in _run\n      self._context.run(self._callback, *self._args)\n    File \"/Users/utkarsh/miniconda3/lib/python3.11/site-packages/ipykernel/kernelbase.py\", line 516, in dispatch_queue\n      await self.process_one()\n    File \"/Users/utkarsh/miniconda3/lib/python3.11/site-packages/ipykernel/kernelbase.py\", line 505, in process_one\n      await dispatch(*args)\n    File \"/Users/utkarsh/miniconda3/lib/python3.11/site-packages/ipykernel/kernelbase.py\", line 412, in dispatch_shell\n      await result\n    File \"/Users/utkarsh/miniconda3/lib/python3.11/site-packages/ipykernel/kernelbase.py\", line 740, in execute_request\n      reply_content = await reply_content\n    File \"/Users/utkarsh/miniconda3/lib/python3.11/site-packages/ipykernel/ipkernel.py\", line 422, in do_execute\n      res = shell.run_cell(\n    File \"/Users/utkarsh/miniconda3/lib/python3.11/site-packages/ipykernel/zmqshell.py\", line 546, in run_cell\n      return super().run_cell(*args, **kwargs)\n    File \"/Users/utkarsh/miniconda3/lib/python3.11/site-packages/IPython/core/interactiveshell.py\", line 3009, in run_cell\n      result = self._run_cell(\n    File \"/Users/utkarsh/miniconda3/lib/python3.11/site-packages/IPython/core/interactiveshell.py\", line 3064, in _run_cell\n      result = runner(coro)\n    File \"/Users/utkarsh/miniconda3/lib/python3.11/site-packages/IPython/core/async_helpers.py\", line 129, in _pseudo_sync_runner\n      coro.send(None)\n    File \"/Users/utkarsh/miniconda3/lib/python3.11/site-packages/IPython/core/interactiveshell.py\", line 3269, in run_cell_async\n      has_raised = await self.run_ast_nodes(code_ast.body, cell_name,\n    File \"/Users/utkarsh/miniconda3/lib/python3.11/site-packages/IPython/core/interactiveshell.py\", line 3448, in run_ast_nodes\n      if await self.run_code(code, result, async_=asy):\n    File \"/Users/utkarsh/miniconda3/lib/python3.11/site-packages/IPython/core/interactiveshell.py\", line 3508, in run_code\n      exec(code_obj, self.user_global_ns, self.user_ns)\n    File \"/var/folders/tw/39r462wj4q10yfxmqddq36l80000gn/T/ipykernel_95151/487288654.py\", line 6, in <module>\n      y_a = model.predict(\n    File \"/Users/utkarsh/miniconda3/lib/python3.11/site-packages/keras/src/utils/traceback_utils.py\", line 65, in error_handler\n      return fn(*args, **kwargs)\n    File \"/Users/utkarsh/miniconda3/lib/python3.11/site-packages/keras/src/engine/training.py\", line 2554, in predict\n      tmp_batch_outputs = self.predict_function(iterator)\n    File \"/Users/utkarsh/miniconda3/lib/python3.11/site-packages/keras/src/engine/training.py\", line 2341, in predict_function\n      return step_function(self, iterator)\n    File \"/Users/utkarsh/miniconda3/lib/python3.11/site-packages/keras/src/engine/training.py\", line 2327, in step_function\n      outputs = model.distribute_strategy.run(run_step, args=(data,))\n    File \"/Users/utkarsh/miniconda3/lib/python3.11/site-packages/keras/src/engine/training.py\", line 2315, in run_step\n      outputs = model.predict_step(data)\n    File \"/Users/utkarsh/miniconda3/lib/python3.11/site-packages/keras/src/engine/training.py\", line 2283, in predict_step\n      return self(x, training=False)\n    File \"/Users/utkarsh/miniconda3/lib/python3.11/site-packages/keras/src/utils/traceback_utils.py\", line 65, in error_handler\n      return fn(*args, **kwargs)\n    File \"/Users/utkarsh/miniconda3/lib/python3.11/site-packages/keras/src/engine/training.py\", line 569, in __call__\n      return super().__call__(*args, **kwargs)\n    File \"/Users/utkarsh/miniconda3/lib/python3.11/site-packages/keras/src/utils/traceback_utils.py\", line 65, in error_handler\n      return fn(*args, **kwargs)\n    File \"/Users/utkarsh/miniconda3/lib/python3.11/site-packages/keras/src/engine/base_layer.py\", line 1150, in __call__\n      outputs = call_fn(inputs, *args, **kwargs)\n    File \"/Users/utkarsh/miniconda3/lib/python3.11/site-packages/keras/src/utils/traceback_utils.py\", line 96, in error_handler\n      return fn(*args, **kwargs)\n    File \"/Users/utkarsh/miniconda3/lib/python3.11/site-packages/keras/src/engine/sequential.py\", line 405, in call\n      return super().call(inputs, training=training, mask=mask)\n    File \"/Users/utkarsh/miniconda3/lib/python3.11/site-packages/keras/src/engine/functional.py\", line 512, in call\n      return self._run_internal_graph(inputs, training=training, mask=mask)\n    File \"/Users/utkarsh/miniconda3/lib/python3.11/site-packages/keras/src/engine/functional.py\", line 669, in _run_internal_graph\n      outputs = node.layer(*args, **kwargs)\n    File \"/Users/utkarsh/miniconda3/lib/python3.11/site-packages/keras/src/utils/traceback_utils.py\", line 65, in error_handler\n      return fn(*args, **kwargs)\n    File \"/Users/utkarsh/miniconda3/lib/python3.11/site-packages/keras/src/engine/base_layer.py\", line 1150, in __call__\n      outputs = call_fn(inputs, *args, **kwargs)\n    File \"/Users/utkarsh/miniconda3/lib/python3.11/site-packages/keras/src/utils/traceback_utils.py\", line 96, in error_handler\n      return fn(*args, **kwargs)\n    File \"/Users/utkarsh/miniconda3/lib/python3.11/site-packages/keras/src/layers/core/dense.py\", line 255, in call\n      outputs = self.activation(outputs)\n    File \"/Users/utkarsh/miniconda3/lib/python3.11/site-packages/keras/src/activations.py\", line 321, in relu\n      return backend.relu(\n    File \"/Users/utkarsh/miniconda3/lib/python3.11/site-packages/keras/src/backend.py\", line 5397, in relu\n      x = tf.nn.relu(x)\nNode: 'sequential/dense/Relu'\nMatrix size-incompatible: In[0]: [1,784], In[1]: [100,100]\n\t [[{{node sequential/dense/Relu}}]] [Op:__inference_predict_function_256]",
     "output_type": "error",
     "traceback": [
      "\u001b[0;31m---------------------------------------------------------------------------\u001b[0m",
      "\u001b[0;31mInvalidArgumentError\u001b[0m                      Traceback (most recent call last)",
      "Cell \u001b[0;32mIn[6], line 6\u001b[0m\n\u001b[1;32m      4\u001b[0m im \u001b[39m=\u001b[39m np\u001b[39m.\u001b[39marray(im)\u001b[39m.\u001b[39mastype(\u001b[39m'\u001b[39m\u001b[39mfloat32\u001b[39m\u001b[39m'\u001b[39m)\n\u001b[1;32m      5\u001b[0m im \u001b[39m=\u001b[39m im\u001b[39m.\u001b[39mreshape(\u001b[39m1\u001b[39m,\u001b[39m-\u001b[39m\u001b[39m1\u001b[39m)\n\u001b[0;32m----> 6\u001b[0m y_a \u001b[39m=\u001b[39m model\u001b[39m.\u001b[39;49mpredict(\n\u001b[1;32m      7\u001b[0m     im,\n\u001b[1;32m      8\u001b[0m     verbose \u001b[39m=\u001b[39;49m \u001b[39m0\u001b[39;49m)\n\u001b[1;32m      9\u001b[0m y_an \u001b[39m=\u001b[39m tf\u001b[39m.\u001b[39mnn\u001b[39m.\u001b[39msoftmax(y_a)\n\u001b[1;32m     10\u001b[0m y_ans \u001b[39m=\u001b[39m \u001b[39mint\u001b[39m(np\u001b[39m.\u001b[39margmax(y_an))\n",
      "File \u001b[0;32m~/miniconda3/lib/python3.11/site-packages/keras/src/utils/traceback_utils.py:70\u001b[0m, in \u001b[0;36mfilter_traceback.<locals>.error_handler\u001b[0;34m(*args, **kwargs)\u001b[0m\n\u001b[1;32m     67\u001b[0m     filtered_tb \u001b[39m=\u001b[39m _process_traceback_frames(e\u001b[39m.\u001b[39m__traceback__)\n\u001b[1;32m     68\u001b[0m     \u001b[39m# To get the full stack trace, call:\u001b[39;00m\n\u001b[1;32m     69\u001b[0m     \u001b[39m# `tf.debugging.disable_traceback_filtering()`\u001b[39;00m\n\u001b[0;32m---> 70\u001b[0m     \u001b[39mraise\u001b[39;00m e\u001b[39m.\u001b[39mwith_traceback(filtered_tb) \u001b[39mfrom\u001b[39;00m \u001b[39mNone\u001b[39;00m\n\u001b[1;32m     71\u001b[0m \u001b[39mfinally\u001b[39;00m:\n\u001b[1;32m     72\u001b[0m     \u001b[39mdel\u001b[39;00m filtered_tb\n",
      "File \u001b[0;32m~/miniconda3/lib/python3.11/site-packages/tensorflow/python/eager/execute.py:53\u001b[0m, in \u001b[0;36mquick_execute\u001b[0;34m(op_name, num_outputs, inputs, attrs, ctx, name)\u001b[0m\n\u001b[1;32m     51\u001b[0m \u001b[39mtry\u001b[39;00m:\n\u001b[1;32m     52\u001b[0m   ctx\u001b[39m.\u001b[39mensure_initialized()\n\u001b[0;32m---> 53\u001b[0m   tensors \u001b[39m=\u001b[39m pywrap_tfe\u001b[39m.\u001b[39mTFE_Py_Execute(ctx\u001b[39m.\u001b[39m_handle, device_name, op_name,\n\u001b[1;32m     54\u001b[0m                                       inputs, attrs, num_outputs)\n\u001b[1;32m     55\u001b[0m \u001b[39mexcept\u001b[39;00m core\u001b[39m.\u001b[39m_NotOkStatusException \u001b[39mas\u001b[39;00m e:\n\u001b[1;32m     56\u001b[0m   \u001b[39mif\u001b[39;00m name \u001b[39mis\u001b[39;00m \u001b[39mnot\u001b[39;00m \u001b[39mNone\u001b[39;00m:\n",
      "\u001b[0;31mInvalidArgumentError\u001b[0m: Graph execution error:\n\nDetected at node 'sequential/dense/Relu' defined at (most recent call last):\n    File \"<frozen runpy>\", line 198, in _run_module_as_main\n    File \"<frozen runpy>\", line 88, in _run_code\n    File \"/Users/utkarsh/miniconda3/lib/python3.11/site-packages/ipykernel_launcher.py\", line 17, in <module>\n      app.launch_new_instance()\n    File \"/Users/utkarsh/miniconda3/lib/python3.11/site-packages/traitlets/config/application.py\", line 1043, in launch_instance\n      app.start()\n    File \"/Users/utkarsh/miniconda3/lib/python3.11/site-packages/ipykernel/kernelapp.py\", line 736, in start\n      self.io_loop.start()\n    File \"/Users/utkarsh/miniconda3/lib/python3.11/site-packages/tornado/platform/asyncio.py\", line 195, in start\n      self.asyncio_loop.run_forever()\n    File \"/Users/utkarsh/miniconda3/lib/python3.11/asyncio/base_events.py\", line 607, in run_forever\n      self._run_once()\n    File \"/Users/utkarsh/miniconda3/lib/python3.11/asyncio/base_events.py\", line 1922, in _run_once\n      handle._run()\n    File \"/Users/utkarsh/miniconda3/lib/python3.11/asyncio/events.py\", line 80, in _run\n      self._context.run(self._callback, *self._args)\n    File \"/Users/utkarsh/miniconda3/lib/python3.11/site-packages/ipykernel/kernelbase.py\", line 516, in dispatch_queue\n      await self.process_one()\n    File \"/Users/utkarsh/miniconda3/lib/python3.11/site-packages/ipykernel/kernelbase.py\", line 505, in process_one\n      await dispatch(*args)\n    File \"/Users/utkarsh/miniconda3/lib/python3.11/site-packages/ipykernel/kernelbase.py\", line 412, in dispatch_shell\n      await result\n    File \"/Users/utkarsh/miniconda3/lib/python3.11/site-packages/ipykernel/kernelbase.py\", line 740, in execute_request\n      reply_content = await reply_content\n    File \"/Users/utkarsh/miniconda3/lib/python3.11/site-packages/ipykernel/ipkernel.py\", line 422, in do_execute\n      res = shell.run_cell(\n    File \"/Users/utkarsh/miniconda3/lib/python3.11/site-packages/ipykernel/zmqshell.py\", line 546, in run_cell\n      return super().run_cell(*args, **kwargs)\n    File \"/Users/utkarsh/miniconda3/lib/python3.11/site-packages/IPython/core/interactiveshell.py\", line 3009, in run_cell\n      result = self._run_cell(\n    File \"/Users/utkarsh/miniconda3/lib/python3.11/site-packages/IPython/core/interactiveshell.py\", line 3064, in _run_cell\n      result = runner(coro)\n    File \"/Users/utkarsh/miniconda3/lib/python3.11/site-packages/IPython/core/async_helpers.py\", line 129, in _pseudo_sync_runner\n      coro.send(None)\n    File \"/Users/utkarsh/miniconda3/lib/python3.11/site-packages/IPython/core/interactiveshell.py\", line 3269, in run_cell_async\n      has_raised = await self.run_ast_nodes(code_ast.body, cell_name,\n    File \"/Users/utkarsh/miniconda3/lib/python3.11/site-packages/IPython/core/interactiveshell.py\", line 3448, in run_ast_nodes\n      if await self.run_code(code, result, async_=asy):\n    File \"/Users/utkarsh/miniconda3/lib/python3.11/site-packages/IPython/core/interactiveshell.py\", line 3508, in run_code\n      exec(code_obj, self.user_global_ns, self.user_ns)\n    File \"/var/folders/tw/39r462wj4q10yfxmqddq36l80000gn/T/ipykernel_95151/487288654.py\", line 6, in <module>\n      y_a = model.predict(\n    File \"/Users/utkarsh/miniconda3/lib/python3.11/site-packages/keras/src/utils/traceback_utils.py\", line 65, in error_handler\n      return fn(*args, **kwargs)\n    File \"/Users/utkarsh/miniconda3/lib/python3.11/site-packages/keras/src/engine/training.py\", line 2554, in predict\n      tmp_batch_outputs = self.predict_function(iterator)\n    File \"/Users/utkarsh/miniconda3/lib/python3.11/site-packages/keras/src/engine/training.py\", line 2341, in predict_function\n      return step_function(self, iterator)\n    File \"/Users/utkarsh/miniconda3/lib/python3.11/site-packages/keras/src/engine/training.py\", line 2327, in step_function\n      outputs = model.distribute_strategy.run(run_step, args=(data,))\n    File \"/Users/utkarsh/miniconda3/lib/python3.11/site-packages/keras/src/engine/training.py\", line 2315, in run_step\n      outputs = model.predict_step(data)\n    File \"/Users/utkarsh/miniconda3/lib/python3.11/site-packages/keras/src/engine/training.py\", line 2283, in predict_step\n      return self(x, training=False)\n    File \"/Users/utkarsh/miniconda3/lib/python3.11/site-packages/keras/src/utils/traceback_utils.py\", line 65, in error_handler\n      return fn(*args, **kwargs)\n    File \"/Users/utkarsh/miniconda3/lib/python3.11/site-packages/keras/src/engine/training.py\", line 569, in __call__\n      return super().__call__(*args, **kwargs)\n    File \"/Users/utkarsh/miniconda3/lib/python3.11/site-packages/keras/src/utils/traceback_utils.py\", line 65, in error_handler\n      return fn(*args, **kwargs)\n    File \"/Users/utkarsh/miniconda3/lib/python3.11/site-packages/keras/src/engine/base_layer.py\", line 1150, in __call__\n      outputs = call_fn(inputs, *args, **kwargs)\n    File \"/Users/utkarsh/miniconda3/lib/python3.11/site-packages/keras/src/utils/traceback_utils.py\", line 96, in error_handler\n      return fn(*args, **kwargs)\n    File \"/Users/utkarsh/miniconda3/lib/python3.11/site-packages/keras/src/engine/sequential.py\", line 405, in call\n      return super().call(inputs, training=training, mask=mask)\n    File \"/Users/utkarsh/miniconda3/lib/python3.11/site-packages/keras/src/engine/functional.py\", line 512, in call\n      return self._run_internal_graph(inputs, training=training, mask=mask)\n    File \"/Users/utkarsh/miniconda3/lib/python3.11/site-packages/keras/src/engine/functional.py\", line 669, in _run_internal_graph\n      outputs = node.layer(*args, **kwargs)\n    File \"/Users/utkarsh/miniconda3/lib/python3.11/site-packages/keras/src/utils/traceback_utils.py\", line 65, in error_handler\n      return fn(*args, **kwargs)\n    File \"/Users/utkarsh/miniconda3/lib/python3.11/site-packages/keras/src/engine/base_layer.py\", line 1150, in __call__\n      outputs = call_fn(inputs, *args, **kwargs)\n    File \"/Users/utkarsh/miniconda3/lib/python3.11/site-packages/keras/src/utils/traceback_utils.py\", line 96, in error_handler\n      return fn(*args, **kwargs)\n    File \"/Users/utkarsh/miniconda3/lib/python3.11/site-packages/keras/src/layers/core/dense.py\", line 255, in call\n      outputs = self.activation(outputs)\n    File \"/Users/utkarsh/miniconda3/lib/python3.11/site-packages/keras/src/activations.py\", line 321, in relu\n      return backend.relu(\n    File \"/Users/utkarsh/miniconda3/lib/python3.11/site-packages/keras/src/backend.py\", line 5397, in relu\n      x = tf.nn.relu(x)\nNode: 'sequential/dense/Relu'\nMatrix size-incompatible: In[0]: [1,784], In[1]: [100,100]\n\t [[{{node sequential/dense/Relu}}]] [Op:__inference_predict_function_256]"
     ]
    }
   ],
   "source": [
    "im = Image.open(r\"img.png\")\n",
    "im = im.resize((30,30)).crop((2, 2, 28, 28)).resize((28,28))\n",
    "im = im.convert(\"L\")\n",
    "im = np.array(im).astype('float32')\n",
    "im = im.reshape(1,-1)\n",
    "y_a = model.predict(\n",
    "    im,\n",
    "    verbose = 0)\n",
    "y_an = tf.nn.softmax(y_a)\n",
    "y_ans = int(np.argmax(y_an))\n",
    "print(y_ans)"
   ]
  },
  {
   "cell_type": "code",
   "execution_count": null,
   "metadata": {},
   "outputs": [],
   "source": []
  }
 ],
 "metadata": {
  "kernelspec": {
   "display_name": "base",
   "language": "python",
   "name": "python3"
  },
  "language_info": {
   "codemirror_mode": {
    "name": "ipython",
    "version": 3
   },
   "file_extension": ".py",
   "mimetype": "text/x-python",
   "name": "python",
   "nbconvert_exporter": "python",
   "pygments_lexer": "ipython3",
   "version": "3.11.4"
  },
  "orig_nbformat": 4
 },
 "nbformat": 4,
 "nbformat_minor": 2
}
